[2020-04-21 05:35:19,370]{/home/alta12/foldervenv/venvpro/lib/python3.6/site-packages/flask/app.py:1892} ERROR - Exception on /client/1 [DELETE]
Traceback (most recent call last):
  File "/home/alta12/foldervenv/venvpro/lib/python3.6/site-packages/sqlalchemy/engine/base.py", line 1248, in _execute_context
    cursor, statement, parameters, context
  File "/home/alta12/foldervenv/venvpro/lib/python3.6/site-packages/sqlalchemy/engine/default.py", line 590, in do_execute
    cursor.execute(statement, parameters)
  File "/home/alta12/foldervenv/venvpro/lib/python3.6/site-packages/pymysql/cursors.py", line 170, in execute
    result = self._query(query)
  File "/home/alta12/foldervenv/venvpro/lib/python3.6/site-packages/pymysql/cursors.py", line 328, in _query
    conn.query(q)
  File "/home/alta12/foldervenv/venvpro/lib/python3.6/site-packages/pymysql/connections.py", line 517, in query
    self._affected_rows = self._read_query_result(unbuffered=unbuffered)
  File "/home/alta12/foldervenv/venvpro/lib/python3.6/site-packages/pymysql/connections.py", line 732, in _read_query_result
    result.read()
  File "/home/alta12/foldervenv/venvpro/lib/python3.6/site-packages/pymysql/connections.py", line 1075, in read
    first_packet = self.connection._read_packet()
  File "/home/alta12/foldervenv/venvpro/lib/python3.6/site-packages/pymysql/connections.py", line 684, in _read_packet
    packet.check_error()
  File "/home/alta12/foldervenv/venvpro/lib/python3.6/site-packages/pymysql/protocol.py", line 220, in check_error
    err.raise_mysql_exception(self._data)
  File "/home/alta12/foldervenv/venvpro/lib/python3.6/site-packages/pymysql/err.py", line 109, in raise_mysql_exception
    raise errorclass(errno, errval)
pymysql.err.InternalError: (1054, "Unknown column 'users.weight' in 'field list'")

The above exception was the direct cause of the following exception:

Traceback (most recent call last):
  File "/home/alta12/foldervenv/venvpro/lib/python3.6/site-packages/flask/app.py", line 1950, in full_dispatch_request
    rv = self.dispatch_request()
  File "/home/alta12/foldervenv/venvpro/lib/python3.6/site-packages/flask/app.py", line 1936, in dispatch_request
    return self.view_functions[rule.endpoint](**req.view_args)
  File "/home/alta12/foldervenv/venvpro/lib/python3.6/site-packages/flask_restful/__init__.py", line 468, in wrapper
    resp = resource(*args, **kwargs)
  File "/home/alta12/foldervenv/venvpro/lib/python3.6/site-packages/flask/views.py", line 89, in view
    return self.dispatch_request(*args, **kwargs)
  File "/home/alta12/foldervenv/venvpro/lib/python3.6/site-packages/flask_restful/__init__.py", line 583, in dispatch_request
    resp = meth(*args, **kwargs)
  File "/home/alta12/Videos/pairprojectAPI/DuoPamungkas/blueprints/client/resources.py", line 74, in delete
    db.session.commit()
  File "/home/alta12/foldervenv/venvpro/lib/python3.6/site-packages/sqlalchemy/orm/scoping.py", line 162, in do
    return getattr(self.registry(), name)(*args, **kwargs)
  File "/home/alta12/foldervenv/venvpro/lib/python3.6/site-packages/sqlalchemy/orm/session.py", line 1036, in commit
    self.transaction.commit()
  File "/home/alta12/foldervenv/venvpro/lib/python3.6/site-packages/sqlalchemy/orm/session.py", line 503, in commit
    self._prepare_impl()
  File "/home/alta12/foldervenv/venvpro/lib/python3.6/site-packages/sqlalchemy/orm/session.py", line 482, in _prepare_impl
    self.session.flush()
  File "/home/alta12/foldervenv/venvpro/lib/python3.6/site-packages/sqlalchemy/orm/session.py", line 2496, in flush
    self._flush(objects)
  File "/home/alta12/foldervenv/venvpro/lib/python3.6/site-packages/sqlalchemy/orm/session.py", line 2637, in _flush
    transaction.rollback(_capture_exception=True)
  File "/home/alta12/foldervenv/venvpro/lib/python3.6/site-packages/sqlalchemy/util/langhelpers.py", line 69, in __exit__
    exc_value, with_traceback=exc_tb,
  File "/home/alta12/foldervenv/venvpro/lib/python3.6/site-packages/sqlalchemy/util/compat.py", line 178, in raise_
    raise exception
  File "/home/alta12/foldervenv/venvpro/lib/python3.6/site-packages/sqlalchemy/orm/session.py", line 2597, in _flush
    flush_context.execute()
  File "/home/alta12/foldervenv/venvpro/lib/python3.6/site-packages/sqlalchemy/orm/unitofwork.py", line 403, in execute
    postsort_actions = self._generate_actions()
  File "/home/alta12/foldervenv/venvpro/lib/python3.6/site-packages/sqlalchemy/orm/unitofwork.py", line 361, in _generate_actions
    if action.execute(self):
  File "/home/alta12/foldervenv/venvpro/lib/python3.6/site-packages/sqlalchemy/orm/unitofwork.py", line 486, in execute
    self.dependency_processor.presort_deletes(uow, delete_states)
  File "/home/alta12/foldervenv/venvpro/lib/python3.6/site-packages/sqlalchemy/orm/dependency.py", line 436, in presort_deletes
    state, self.key, self._passive_delete_flag
  File "/home/alta12/foldervenv/venvpro/lib/python3.6/site-packages/sqlalchemy/orm/unitofwork.py", line 249, in get_attribute_history
    state, state.dict, passive | attributes.LOAD_AGAINST_COMMITTED
  File "/home/alta12/foldervenv/venvpro/lib/python3.6/site-packages/sqlalchemy/orm/attributes.py", line 939, in get_history
    current = self.get(state, dict_, passive=passive)
  File "/home/alta12/foldervenv/venvpro/lib/python3.6/site-packages/sqlalchemy/orm/attributes.py", line 722, in get
    value = self.callable_(state, passive)
  File "/home/alta12/foldervenv/venvpro/lib/python3.6/site-packages/sqlalchemy/orm/strategies.py", line 750, in _load_for_state
    session, state, primary_key_identity, passive
  File "<string>", line 1, in <lambda>
  File "/home/alta12/foldervenv/venvpro/lib/python3.6/site-packages/sqlalchemy/orm/strategies.py", line 892, in _emit_lazyload
    .with_post_criteria(set_default_params)
  File "/home/alta12/foldervenv/venvpro/lib/python3.6/site-packages/sqlalchemy/ext/baked.py", line 544, in all
    return list(self)
  File "/home/alta12/foldervenv/venvpro/lib/python3.6/site-packages/sqlalchemy/ext/baked.py", line 444, in __iter__
    return q._execute_and_instances(context)
  File "/home/alta12/foldervenv/venvpro/lib/python3.6/site-packages/sqlalchemy/orm/query.py", line 3430, in _execute_and_instances
    result = conn.execute(querycontext.statement, self._params)
  File "/home/alta12/foldervenv/venvpro/lib/python3.6/site-packages/sqlalchemy/engine/base.py", line 984, in execute
    return meth(self, multiparams, params)
  File "/home/alta12/foldervenv/venvpro/lib/python3.6/site-packages/sqlalchemy/sql/elements.py", line 293, in _execute_on_connection
    return connection._execute_clauseelement(self, multiparams, params)
  File "/home/alta12/foldervenv/venvpro/lib/python3.6/site-packages/sqlalchemy/engine/base.py", line 1103, in _execute_clauseelement
    distilled_params,
  File "/home/alta12/foldervenv/venvpro/lib/python3.6/site-packages/sqlalchemy/engine/base.py", line 1288, in _execute_context
    e, statement, parameters, cursor, context
  File "/home/alta12/foldervenv/venvpro/lib/python3.6/site-packages/sqlalchemy/engine/base.py", line 1482, in _handle_dbapi_exception
    sqlalchemy_exception, with_traceback=exc_info[2], from_=e
  File "/home/alta12/foldervenv/venvpro/lib/python3.6/site-packages/sqlalchemy/util/compat.py", line 178, in raise_
    raise exception
  File "/home/alta12/foldervenv/venvpro/lib/python3.6/site-packages/sqlalchemy/engine/base.py", line 1248, in _execute_context
    cursor, statement, parameters, context
  File "/home/alta12/foldervenv/venvpro/lib/python3.6/site-packages/sqlalchemy/engine/default.py", line 590, in do_execute
    cursor.execute(statement, parameters)
  File "/home/alta12/foldervenv/venvpro/lib/python3.6/site-packages/pymysql/cursors.py", line 170, in execute
    result = self._query(query)
  File "/home/alta12/foldervenv/venvpro/lib/python3.6/site-packages/pymysql/cursors.py", line 328, in _query
    conn.query(q)
  File "/home/alta12/foldervenv/venvpro/lib/python3.6/site-packages/pymysql/connections.py", line 517, in query
    self._affected_rows = self._read_query_result(unbuffered=unbuffered)
  File "/home/alta12/foldervenv/venvpro/lib/python3.6/site-packages/pymysql/connections.py", line 732, in _read_query_result
    result.read()
  File "/home/alta12/foldervenv/venvpro/lib/python3.6/site-packages/pymysql/connections.py", line 1075, in read
    first_packet = self.connection._read_packet()
  File "/home/alta12/foldervenv/venvpro/lib/python3.6/site-packages/pymysql/connections.py", line 684, in _read_packet
    packet.check_error()
  File "/home/alta12/foldervenv/venvpro/lib/python3.6/site-packages/pymysql/protocol.py", line 220, in check_error
    err.raise_mysql_exception(self._data)
  File "/home/alta12/foldervenv/venvpro/lib/python3.6/site-packages/pymysql/err.py", line 109, in raise_mysql_exception
    raise errorclass(errno, errval)
sqlalchemy.exc.InternalError: (pymysql.err.InternalError) (1054, "Unknown column 'users.weight' in 'field list'")
[SQL: SELECT users.id AS users_id, users.client_id AS users_client_id, users.name AS users_name, users.age AS users_age, users.sex AS users_sex, users.weight AS users_weight, users.height AS users_height, users.food AS users_food 
FROM users 
WHERE %(param_1)s = users.client_id]
[parameters: {'param_1': 1}]
(Background on this error at: http://sqlalche.me/e/2j85)
[2020-04-21 05:35:19,375]{/home/alta12/Videos/pairprojectAPI/DuoPamungkas/blueprints/__init__.py:55} ERROR - 
[2020-04-21 05:36:31,082]{/home/alta12/foldervenv/venvpro/lib/python3.6/site-packages/flask/app.py:1892} ERROR - Exception on /client/1 [DELETE]
Traceback (most recent call last):
  File "/home/alta12/foldervenv/venvpro/lib/python3.6/site-packages/sqlalchemy/engine/base.py", line 1248, in _execute_context
    cursor, statement, parameters, context
  File "/home/alta12/foldervenv/venvpro/lib/python3.6/site-packages/sqlalchemy/engine/default.py", line 590, in do_execute
    cursor.execute(statement, parameters)
  File "/home/alta12/foldervenv/venvpro/lib/python3.6/site-packages/pymysql/cursors.py", line 170, in execute
    result = self._query(query)
  File "/home/alta12/foldervenv/venvpro/lib/python3.6/site-packages/pymysql/cursors.py", line 328, in _query
    conn.query(q)
  File "/home/alta12/foldervenv/venvpro/lib/python3.6/site-packages/pymysql/connections.py", line 517, in query
    self._affected_rows = self._read_query_result(unbuffered=unbuffered)
  File "/home/alta12/foldervenv/venvpro/lib/python3.6/site-packages/pymysql/connections.py", line 732, in _read_query_result
    result.read()
  File "/home/alta12/foldervenv/venvpro/lib/python3.6/site-packages/pymysql/connections.py", line 1075, in read
    first_packet = self.connection._read_packet()
  File "/home/alta12/foldervenv/venvpro/lib/python3.6/site-packages/pymysql/connections.py", line 684, in _read_packet
    packet.check_error()
  File "/home/alta12/foldervenv/venvpro/lib/python3.6/site-packages/pymysql/protocol.py", line 220, in check_error
    err.raise_mysql_exception(self._data)
  File "/home/alta12/foldervenv/venvpro/lib/python3.6/site-packages/pymysql/err.py", line 109, in raise_mysql_exception
    raise errorclass(errno, errval)
pymysql.err.InternalError: (1054, "Unknown column 'users.weight' in 'field list'")

The above exception was the direct cause of the following exception:

Traceback (most recent call last):
  File "/home/alta12/foldervenv/venvpro/lib/python3.6/site-packages/flask/app.py", line 1950, in full_dispatch_request
    rv = self.dispatch_request()
  File "/home/alta12/foldervenv/venvpro/lib/python3.6/site-packages/flask/app.py", line 1936, in dispatch_request
    return self.view_functions[rule.endpoint](**req.view_args)
  File "/home/alta12/foldervenv/venvpro/lib/python3.6/site-packages/flask_restful/__init__.py", line 468, in wrapper
    resp = resource(*args, **kwargs)
  File "/home/alta12/foldervenv/venvpro/lib/python3.6/site-packages/flask/views.py", line 89, in view
    return self.dispatch_request(*args, **kwargs)
  File "/home/alta12/foldervenv/venvpro/lib/python3.6/site-packages/flask_restful/__init__.py", line 583, in dispatch_request
    resp = meth(*args, **kwargs)
  File "/home/alta12/Videos/pairprojectAPI/DuoPamungkas/blueprints/client/resources.py", line 74, in delete
    db.session.commit()
  File "/home/alta12/foldervenv/venvpro/lib/python3.6/site-packages/sqlalchemy/orm/scoping.py", line 162, in do
    return getattr(self.registry(), name)(*args, **kwargs)
  File "/home/alta12/foldervenv/venvpro/lib/python3.6/site-packages/sqlalchemy/orm/session.py", line 1036, in commit
    self.transaction.commit()
  File "/home/alta12/foldervenv/venvpro/lib/python3.6/site-packages/sqlalchemy/orm/session.py", line 503, in commit
    self._prepare_impl()
  File "/home/alta12/foldervenv/venvpro/lib/python3.6/site-packages/sqlalchemy/orm/session.py", line 482, in _prepare_impl
    self.session.flush()
  File "/home/alta12/foldervenv/venvpro/lib/python3.6/site-packages/sqlalchemy/orm/session.py", line 2496, in flush
    self._flush(objects)
  File "/home/alta12/foldervenv/venvpro/lib/python3.6/site-packages/sqlalchemy/orm/session.py", line 2637, in _flush
    transaction.rollback(_capture_exception=True)
  File "/home/alta12/foldervenv/venvpro/lib/python3.6/site-packages/sqlalchemy/util/langhelpers.py", line 69, in __exit__
    exc_value, with_traceback=exc_tb,
  File "/home/alta12/foldervenv/venvpro/lib/python3.6/site-packages/sqlalchemy/util/compat.py", line 178, in raise_
    raise exception
  File "/home/alta12/foldervenv/venvpro/lib/python3.6/site-packages/sqlalchemy/orm/session.py", line 2597, in _flush
    flush_context.execute()
  File "/home/alta12/foldervenv/venvpro/lib/python3.6/site-packages/sqlalchemy/orm/unitofwork.py", line 403, in execute
    postsort_actions = self._generate_actions()
  File "/home/alta12/foldervenv/venvpro/lib/python3.6/site-packages/sqlalchemy/orm/unitofwork.py", line 361, in _generate_actions
    if action.execute(self):
  File "/home/alta12/foldervenv/venvpro/lib/python3.6/site-packages/sqlalchemy/orm/unitofwork.py", line 486, in execute
    self.dependency_processor.presort_deletes(uow, delete_states)
  File "/home/alta12/foldervenv/venvpro/lib/python3.6/site-packages/sqlalchemy/orm/dependency.py", line 436, in presort_deletes
    state, self.key, self._passive_delete_flag
  File "/home/alta12/foldervenv/venvpro/lib/python3.6/site-packages/sqlalchemy/orm/unitofwork.py", line 249, in get_attribute_history
    state, state.dict, passive | attributes.LOAD_AGAINST_COMMITTED
  File "/home/alta12/foldervenv/venvpro/lib/python3.6/site-packages/sqlalchemy/orm/attributes.py", line 939, in get_history
    current = self.get(state, dict_, passive=passive)
  File "/home/alta12/foldervenv/venvpro/lib/python3.6/site-packages/sqlalchemy/orm/attributes.py", line 722, in get
    value = self.callable_(state, passive)
  File "/home/alta12/foldervenv/venvpro/lib/python3.6/site-packages/sqlalchemy/orm/strategies.py", line 750, in _load_for_state
    session, state, primary_key_identity, passive
  File "<string>", line 1, in <lambda>
  File "/home/alta12/foldervenv/venvpro/lib/python3.6/site-packages/sqlalchemy/orm/strategies.py", line 892, in _emit_lazyload
    .with_post_criteria(set_default_params)
  File "/home/alta12/foldervenv/venvpro/lib/python3.6/site-packages/sqlalchemy/ext/baked.py", line 544, in all
    return list(self)
  File "/home/alta12/foldervenv/venvpro/lib/python3.6/site-packages/sqlalchemy/ext/baked.py", line 444, in __iter__
    return q._execute_and_instances(context)
  File "/home/alta12/foldervenv/venvpro/lib/python3.6/site-packages/sqlalchemy/orm/query.py", line 3430, in _execute_and_instances
    result = conn.execute(querycontext.statement, self._params)
  File "/home/alta12/foldervenv/venvpro/lib/python3.6/site-packages/sqlalchemy/engine/base.py", line 984, in execute
    return meth(self, multiparams, params)
  File "/home/alta12/foldervenv/venvpro/lib/python3.6/site-packages/sqlalchemy/sql/elements.py", line 293, in _execute_on_connection
    return connection._execute_clauseelement(self, multiparams, params)
  File "/home/alta12/foldervenv/venvpro/lib/python3.6/site-packages/sqlalchemy/engine/base.py", line 1103, in _execute_clauseelement
    distilled_params,
  File "/home/alta12/foldervenv/venvpro/lib/python3.6/site-packages/sqlalchemy/engine/base.py", line 1288, in _execute_context
    e, statement, parameters, cursor, context
  File "/home/alta12/foldervenv/venvpro/lib/python3.6/site-packages/sqlalchemy/engine/base.py", line 1482, in _handle_dbapi_exception
    sqlalchemy_exception, with_traceback=exc_info[2], from_=e
  File "/home/alta12/foldervenv/venvpro/lib/python3.6/site-packages/sqlalchemy/util/compat.py", line 178, in raise_
    raise exception
  File "/home/alta12/foldervenv/venvpro/lib/python3.6/site-packages/sqlalchemy/engine/base.py", line 1248, in _execute_context
    cursor, statement, parameters, context
  File "/home/alta12/foldervenv/venvpro/lib/python3.6/site-packages/sqlalchemy/engine/default.py", line 590, in do_execute
    cursor.execute(statement, parameters)
  File "/home/alta12/foldervenv/venvpro/lib/python3.6/site-packages/pymysql/cursors.py", line 170, in execute
    result = self._query(query)
  File "/home/alta12/foldervenv/venvpro/lib/python3.6/site-packages/pymysql/cursors.py", line 328, in _query
    conn.query(q)
  File "/home/alta12/foldervenv/venvpro/lib/python3.6/site-packages/pymysql/connections.py", line 517, in query
    self._affected_rows = self._read_query_result(unbuffered=unbuffered)
  File "/home/alta12/foldervenv/venvpro/lib/python3.6/site-packages/pymysql/connections.py", line 732, in _read_query_result
    result.read()
  File "/home/alta12/foldervenv/venvpro/lib/python3.6/site-packages/pymysql/connections.py", line 1075, in read
    first_packet = self.connection._read_packet()
  File "/home/alta12/foldervenv/venvpro/lib/python3.6/site-packages/pymysql/connections.py", line 684, in _read_packet
    packet.check_error()
  File "/home/alta12/foldervenv/venvpro/lib/python3.6/site-packages/pymysql/protocol.py", line 220, in check_error
    err.raise_mysql_exception(self._data)
  File "/home/alta12/foldervenv/venvpro/lib/python3.6/site-packages/pymysql/err.py", line 109, in raise_mysql_exception
    raise errorclass(errno, errval)
sqlalchemy.exc.InternalError: (pymysql.err.InternalError) (1054, "Unknown column 'users.weight' in 'field list'")
[SQL: SELECT users.id AS users_id, users.client_id AS users_client_id, users.name AS users_name, users.age AS users_age, users.sex AS users_sex, users.weight AS users_weight, users.height AS users_height, users.food AS users_food 
FROM users 
WHERE %(param_1)s = users.client_id]
[parameters: {'param_1': 1}]
(Background on this error at: http://sqlalche.me/e/2j85)
[2020-04-21 05:36:31,096]{/home/alta12/Videos/pairprojectAPI/DuoPamungkas/blueprints/__init__.py:55} ERROR - 
[2020-04-21 05:37:56,653]{/home/alta12/Videos/pairprojectAPI/DuoPamungkas/blueprints/__init__.py:51} WARNING - REQUEST_LOG	{"request": {}, "response": []}
[2020-04-21 05:38:00,895]{/home/alta12/Videos/pairprojectAPI/DuoPamungkas/blueprints/__init__.py:51} WARNING - REQUEST_LOG	{"request": {}, "response": {"id": 1, "client_key": "asa", "client_secret": "241d909957b43b1ac992a0863e93a6863539827fddb4514ff8a3d8b744847365f2a50774614428232cdfc8757249c876c466e931845e6d2f11cbdade8cc27a7d", "status": "False"}}
[2020-04-21 05:38:39,231]{/home/alta12/Videos/pairprojectAPI/DuoPamungkas/blueprints/__init__.py:51} WARNING - REQUEST_LOG	{"request": {}, "response": {"id": 2, "client_key": "internal", "client_secret": "95e5a152810bcab3fcad9087e60cb596989592cf9b2effe5984d7d956e604e86e7fdf4f933dbaf12eba7222923427620e9aeeffac7544ef4a4b8f7c20aa18a33", "status": "True"}}
[2020-04-21 05:38:43,704]{/home/alta12/Videos/pairprojectAPI/DuoPamungkas/blueprints/__init__.py:51} WARNING - REQUEST_LOG	{"request": {}, "response": [{"id": 1, "client_key": "asa", "client_secret": "241d909957b43b1ac992a0863e93a6863539827fddb4514ff8a3d8b744847365f2a50774614428232cdfc8757249c876c466e931845e6d2f11cbdade8cc27a7d", "status": "False"}, {"id": 2, "client_key": "internal", "client_secret": "95e5a152810bcab3fcad9087e60cb596989592cf9b2effe5984d7d956e604e86e7fdf4f933dbaf12eba7222923427620e9aeeffac7544ef4a4b8f7c20aa18a33", "status": "True"}]}
[2020-04-21 05:40:48,948]{/home/alta12/Videos/pairprojectAPI/DuoPamungkas/blueprints/__init__.py:55} ERROR - 
[2020-04-21 05:40:57,625]{/home/alta12/foldervenv/venvpro/lib/python3.6/site-packages/flask/app.py:1892} ERROR - Exception on /auth [GET]
Traceback (most recent call last):
  File "/home/alta12/foldervenv/venvpro/lib/python3.6/site-packages/flask/app.py", line 1950, in full_dispatch_request
    rv = self.dispatch_request()
  File "/home/alta12/foldervenv/venvpro/lib/python3.6/site-packages/flask/app.py", line 1936, in dispatch_request
    return self.view_functions[rule.endpoint](**req.view_args)
  File "/home/alta12/foldervenv/venvpro/lib/python3.6/site-packages/flask_restful/__init__.py", line 468, in wrapper
    resp = resource(*args, **kwargs)
  File "/home/alta12/foldervenv/venvpro/lib/python3.6/site-packages/flask/views.py", line 89, in view
    return self.dispatch_request(*args, **kwargs)
  File "/home/alta12/foldervenv/venvpro/lib/python3.6/site-packages/flask_restful/__init__.py", line 583, in dispatch_request
    resp = meth(*args, **kwargs)
  File "/home/alta12/Videos/pairprojectAPI/DuoPamungkas/blueprints/auth/__init__.py", line 28, in get
    qry = marshal(qry, Clients.jwt_claim_fields)
AttributeError: type object 'Clients' has no attribute 'jwt_claim_fields'
[2020-04-21 05:40:57,627]{/home/alta12/Videos/pairprojectAPI/DuoPamungkas/blueprints/__init__.py:55} ERROR - 
[2020-04-21 05:41:08,774]{/home/alta12/Videos/pairprojectAPI/DuoPamungkas/blueprints/__init__.py:51} WARNING - REQUEST_LOG	{"request": {"client_key": "asa", "client_secret": "alta123"}, "response": null}
[2020-04-21 05:41:58,294]{/home/alta12/foldervenv/venvpro/lib/python3.6/site-packages/flask/app.py:1892} ERROR - Exception on /auth [GET]
Traceback (most recent call last):
  File "/home/alta12/foldervenv/venvpro/lib/python3.6/site-packages/flask/app.py", line 1950, in full_dispatch_request
    rv = self.dispatch_request()
  File "/home/alta12/foldervenv/venvpro/lib/python3.6/site-packages/flask/app.py", line 1936, in dispatch_request
    return self.view_functions[rule.endpoint](**req.view_args)
  File "/home/alta12/foldervenv/venvpro/lib/python3.6/site-packages/flask_restful/__init__.py", line 468, in wrapper
    resp = resource(*args, **kwargs)
  File "/home/alta12/foldervenv/venvpro/lib/python3.6/site-packages/flask/views.py", line 89, in view
    return self.dispatch_request(*args, **kwargs)
  File "/home/alta12/foldervenv/venvpro/lib/python3.6/site-packages/flask_restful/__init__.py", line 583, in dispatch_request
    resp = meth(*args, **kwargs)
  File "/home/alta12/Videos/pairprojectAPI/DuoPamungkas/blueprints/auth/__init__.py", line 28, in get
    qry = marshal(qry, Clients.jwt_claim_fields)
AttributeError: type object 'Clients' has no attribute 'jwt_claim_fields'
[2020-04-21 05:41:58,294]{/home/alta12/Videos/pairprojectAPI/DuoPamungkas/blueprints/__init__.py:55} ERROR - 
[2020-04-21 05:42:48,749]{/home/alta12/Videos/pairprojectAPI/DuoPamungkas/blueprints/__init__.py:51} WARNING - REQUEST_LOG	{"request": {"client_key": "internal", "client_secret": "th1s1s1nt3n4lcl13nt"}, "response": {"token": "eyJ0eXAiOiJKV1QiLCJhbGciOiJIUzI1NiJ9.eyJpYXQiOjE1ODc0NjIxNjgsIm5iZiI6MTU4NzQ2MjE2OCwianRpIjoiNWVjNTY3NWQtMTg5ZS00ZjExLWI1N2QtZGMwODg3Y2ZkZjhiIiwiZXhwIjoxNTg3NTQ4NTY4LCJpZGVudGl0eSI6ImludGVybmFsIiwiZnJlc2giOmZhbHNlLCJ0eXBlIjoiYWNjZXNzIiwidXNlcl9jbGFpbXMiOnsiaWRlbnRpZmllciI6ImFsdGEgYmF0Y2ggNSIsInN0YXR1cyI6IlRydWUifX0.dp8G9Ch3hR1GZqMrwMOOvVAJW5yIddwb1XRT2K-nsjs"}}
[2020-04-21 05:45:36,475]{/home/alta12/foldervenv/venvpro/lib/python3.6/site-packages/flask/app.py:1892} ERROR - Exception on /client [GET]
Traceback (most recent call last):
  File "/home/alta12/foldervenv/venvpro/lib/python3.6/site-packages/flask/app.py", line 1950, in full_dispatch_request
    rv = self.dispatch_request()
  File "/home/alta12/foldervenv/venvpro/lib/python3.6/site-packages/flask/app.py", line 1936, in dispatch_request
    return self.view_functions[rule.endpoint](**req.view_args)
  File "/home/alta12/foldervenv/venvpro/lib/python3.6/site-packages/flask_restful/__init__.py", line 468, in wrapper
    resp = resource(*args, **kwargs)
  File "/home/alta12/foldervenv/venvpro/lib/python3.6/site-packages/flask/views.py", line 88, in view
    self = view.view_class(*class_args, **class_kwargs)
  File "/home/alta12/Videos/pairprojectAPI/DuoPamungkas/blueprints/__init__.py", line 20, in wrapper
    verify_jwt_in_request()
  File "/home/alta12/foldervenv/venvpro/lib/python3.6/site-packages/flask_jwt_extended/view_decorators.py", line 32, in verify_jwt_in_request
    jwt_data, jwt_header = _decode_jwt_from_request(request_type='access')
  File "/home/alta12/foldervenv/venvpro/lib/python3.6/site-packages/flask_jwt_extended/view_decorators.py", line 314, in _decode_jwt_from_request
    raise NoAuthorizationError(errors[0])
flask_jwt_extended.exceptions.NoAuthorizationError: Missing Authorization Header
[2020-04-21 05:45:36,478]{/home/alta12/Videos/pairprojectAPI/DuoPamungkas/blueprints/__init__.py:55} ERROR - 
[2020-04-21 05:45:58,049]{/home/alta12/Videos/pairprojectAPI/DuoPamungkas/blueprints/__init__.py:51} WARNING - REQUEST_LOG	{"request": {}, "response": [{"id": 1, "client_key": "asa", "client_secret": "241d909957b43b1ac992a0863e93a6863539827fddb4514ff8a3d8b744847365f2a50774614428232cdfc8757249c876c466e931845e6d2f11cbdade8cc27a7d", "status": "False"}, {"id": 2, "client_key": "internal", "client_secret": "95e5a152810bcab3fcad9087e60cb596989592cf9b2effe5984d7d956e604e86e7fdf4f933dbaf12eba7222923427620e9aeeffac7544ef4a4b8f7c20aa18a33", "status": "True"}]}
